Workbook
Name shiva: Practice!$BA$6

Sheet Sheet1
A3: Row Labels | B3: Sum of FinalPrice
A4: Cancelled | B4: 5368151.7
A5: Delivered | B5: 7650453.1
A6: In-Progress | B6: 6788174.6
A7: Returned | B7: 6828120.1
A8: Grand Total | B8: 26634900

Sheet Amazon_Data
A1: OrderID | B1: CustomerName | C1: Email | D1: Location | E1: Brand | F1: Model | G1: OrderDate | H1: DeliveryDate | I1: Quantity | J1: UnitPrice | K1: Discounts% | L1: OrderStatus | M1: FinalPrice | N1: PaymentType | O1: ShipmentPartner | P1: SellerID | Q1: SellerName | R1: SellerRating | S1: SellerJoinDate | T1: SLA_Days | U1: RefundAmount
A2: ORD0001 | B2: Zoya Verma | C2: zoya.verma86@gmail.com | D2: Ahmedabad | E2: Mi | F2: Mi Soundbar | G2: 2020-06-20 | H2: 44013 | I2: 4 | J2: 77523 | K2: 0.1 | L2: =Amazon[[#This Row],[Quantity]]*Amazon[[#This Row],[UnitPrice]]*#REF!% -> #REF! | M2: 279082.8 | N2: COD | O2: Delhivery | P2: SEL3424 | Q2: MegaTech Store | R2: 3.3 | S2: 2010-09-07 | T2: 0 | U2: 0
A3: ORD0002 | B3: Sanjay Kapoor | C3: sanjay.kapoor32@gmail.com | D3: Chennai | E3: Vivo | F3: Vivo X80 | G3: 2023-06-03 | H3: 45084 | I3: 1 | J3: 92974 | K3: 0 | L3: Cancelled | M3: 92974 | N3: Coupon | O3: Delhivery | P3: SEL2649 | Q3: ElectroHub | R3: 3.4 | S3: 2018-03-02 | T3: 0 | U3: 0
A4: ORD0003 | B4: Amit Gupta | C4: amit.gupta78@gmail.com | D4: Hyderabad | E4: ZTE | F4: ZTE Blade A7 | G4: 2021-10-18 | H4: 44496 | I4: 2 | J4: 66773 | K4: 0.05 | L4: Cancelled | M4: 126868.7 | N4: Coupon | O4: Ekart | P4: SEL9586 | Q4: DigitalMart | R4: 3.6 | S4: 2012-11-29 | T4: 0 | U4: 0
A5: ORD0004 | B5: Hitesh Verma | C5: hitesh.verma46@gmail.com | D5: Delhi | E5: ZTE | F5: ZTE Blade A7 | G5: 2023-04-27 | H5: 45049 | I5: 5 | J5: 46382 | K5: 0.2 | L5: Cancelled | M5: 185528 | N5: Card | O5: Ekart | P5: SEL4758 | Q5: GadgetWorld | R5: 4.8 | S5: 2019-03-20 | T5: 0 | U5: 0
A6: ORD0005 | B6: Hitesh Sharma | C6: hitesh.sharma55@gmail.com | D6: Mumbai | E6: LG | F6: LG Washing Machine | G6: 2024-06-04 | H6: 45456 | I6: 3 | J6: 46518 | K6: 0.05 | L6: Cancelled | M6: 132576.3 | N6: Coupon | O6: Ekart | P6: SEL5186 | Q6: Prime Electronics | R6: 4 | S6: 2020-07-31 | T6: 0 | U6: 0
A7: ORD0006 | B7: Lakshmi Reddy | C7: lakshmi.reddy42@gmail.com | D7: Mumbai | E7: HTC | F7: HTC Desire 12 | G7: 2024-08-31 | H7: 45540 | I7: 3 | J7: 26057 | K7: 0.2 | L7: In-Progress | M7: 62536.8 | N7: UPI | O7: Delhivery | P7: SEL7335 | Q7: DigitalMart | R7: 2.9 | S7: 2015-05-15 | T7: 9 | U7: 0
A8: ORD0007 | B8: Pooja Iyer | C8: pooja.iyer89@gmail.com | D8: Kochi | E8: Dell | F8: XPS 13 | G8: 2023-04-15 | H8: 45038 | I8: 2 | J8: 25771 | K8: 0.15 | L8: Delivered | M8: 43810.7 | N8: Card | O8: BlueDart | P8: SEL2075 | Q8: Amazons | R8: 3.4 | S8: 2018-02-24 | T8: 0 | U8: 0
A9: ORD0008 | B9: Hitesh Reddy | C9: hitesh.reddy74@gmail.com | D9: Ahmedabad | E9: Apple | F9: iPhone 13 | G9: 2023-08-12 | H9: 45157 | I9: 5 | J9: 56748 | K9: 0.05 | L9: In-Progress | M9: 269553 | N9: Card | O9: ExpressBees | P9: SEL5332 | Q9: BestDeals | R9: 3.4 | S9: 2020-05-30 | T9: 6 | U9: 0
A10: ORD0009 | B10: Arjun Patel | C10: arjun.patel90@gmail.com | D10: Mumbai | E10: Apple | F10: MacBook Pro | G10: 2022-06-23 | H10: 44746 | I10: 5 | J10: 57083 | K10: 0.15 | L10: In-Progress | M10: 242602.75 | N10: UPI | O10: ExpressBees | P10: SEL4037 | Q10: MegaTech Store | R10: 3.3 | S10: 2014-11-09 | T10: 10 | U10: 0
A11: ORD0010 | B11: Ravi Verma | C11: ravi.verma87@gmail.com | D11: Bengaluru | E11: Mi | F11: Mi TV 4A | G11: 2022-03-18 | H11: 44644 | I11: 5 | J11: 92803 | K11: 0.05 | L11: Delivered | M11: 440814.25 | N11: COD | O11: BlueDart | P11: SEL5133 | Q11: MegaTech Store | R11: 3.3 | S11: 2018-07-06 | T11: 0 | U11: 0
A12: ORD0011 | B12: Amit Sharma | C12: amit.sharma93@gmail.com | D12: Chennai | E12: LG | F12: LG AC 1.5T | G12: 2021-10-13 | H12: 44487 | I12: 1 | J12: 58549 | K12: 0.1 | L12: In-Progress | M12: 52694.1 | N12: COD | O12: BlueDart | P12: SEL4311 | Q12: ElectroHub | R12: 3.4 | S12: 2015-08-16 | T12: 6 | U12: 0
A13: ORD0012 | B13: Amit Verma | C13: amit.verma39@gmail.com | D13: Kochi | E13: Oppo | F13: Oppo A54 | G13: 2022-01-04 | H13: 44573 | I13: 3 | J13: 104023 | K13: 0.1 | L13: Returned | M13: 280862.1 | N13: Card | O13: Delhivery | P13: SEL5976 | Q13: DigitalMart | R13: 3.6 | S13: 2019-11-20 | T13: 0 | U13: 280862.1
A14: ORD0013 | B14: Neha Gupta | C14: neha.gupta32@gmail.com | D14: Bengaluru | E14: LG | F14: LG Washing Machine | G14: 2020-02-27 | H14: 43898 | I14: 4 | J14: 34113 | K14: 0.1 | L14: Delivered | M14: 122806.8 | N14: COD | O14: BlueDart | P14: SEL7923 | Q14: GadgetWorld | R14: 4.8 | S14: 2010-05-22 | T14: 0 | U14: 0
... A151: ORD0150 | B151: Hitesh Iyer | C151: hitesh.iyer75@gmail.com | D151: Ahmedabad | E151: Sony | F151: Sony Bravia 50 | G151: 2019-10-21 | H151: 43767 | I151: 3 | J151: 57551 | K151: 0.15 | L151: Returned | M151: 146755.05 | N151: Card | O151: BlueDart | P151: SEL1760 | Q151: DigitalMart | R151: 2.9 | S151: 2015-10-09 | T151: 0 | U151: 146755.05

Sheet Questions
A1: ✅ 💚 PART 1 — 20 Beginner Level (Simple + Tricky)
A3: Focus: basic formulas, text, date, min/max, logical.
A4: 1. Extract the first 3 letters of each Brand.
A6: (Hint: LEFT)
A8: 2. Extract the last 2 digits from SellerID.
A10: (Hint: RIGHT)
A12: 3. Convert all Customer Names to UPPERCASE.
A14: (Hint: UPPER)
A16: 4. Find the total revenue (Sum of FinalPrice).
A18: 5. Count how many orders were DELIVERED.
A20: (Hint: COUNTIF)
A22: 6. Count orders from location “Bengaluru”.
... A229: Total Revenue, Year Growth %, Avg Rating, Return Rate, Top Brand**

Sheet nari

Sheet Practice
A1: Fetching first 3 letters from Brand | C1: Fetching first 3 letters from Brand with conver UPPER | E1: Extract last 2 digits from seller id | G1: Convert all customer names to upper case | I1: Sum of sales worth ordered | K1: =SUM(Amazon[FinalPrice]) -> 26634900
A2: =LEFT(Amazon[Brand],3) -> Mi | C2: =UPPER(LEFT(Amazon[Brand],3)) -> MI | E2: =LOWER(RIGHT(Amazon[SellerID],2)) -> 24 | G2: =UPPER(Amazon[CustomerName]) -> ZOYA VERMA | I2: =SUM(Amazon[FinalPrice]) -> 26634900 | Z2: =IF(Amazon[SellerRating]>=4,"true","false") -> false | AA2: =COUNTIFS(Amazon_Data!N:N,Amazon_Data!N7) -> 36 | BK2: =ABS(_xlfn.DAYS(Amazon[OrderDate],Amazon[DeliveryDate])) -> 11
A3: =LEFT(Amazon[Brand],3) -> Viv | C3: =UPPER(LEFT(Amazon[Brand],3)) -> VIV | E3: =LOWER(RIGHT(Amazon[SellerID],2)) -> 49 | G3: =UPPER(Amazon[CustomerName]) -> SANJAY KAPOOR | Z3: =IF(Amazon[SellerRating]>=4,"true","false") -> false | AI3: Mi | AJ3: =SUMIFS(Amazon[FinalPrice],Amazon[Brand],AI3) -> 3796963.3 | BK3: =ABS(_xlfn.DAYS(Amazon[OrderDate],Amazon[DeliveryDate])) -> 4
A4: =LEFT(Amazon[Brand],3) -> ZTE | C4: =UPPER(LEFT(Amazon[Brand],3)) -> ZTE | E4: =LOWER(RIGHT(Amazon[SellerID],2)) -> 86 | G4: =UPPER(Amazon[CustomerName]) -> AMIT GUPTA | I4: Where Delivered revenue.. Using sumif | Z4: =IF(Amazon[SellerRating]>=4,"true","false") -> false | AI4: Vivo | AJ4: =SUMIFS(Amazon[FinalPrice],Amazon[Brand],AI4) -> 1754912.6 | BK4: =ABS(_xlfn.DAYS(Amazon[OrderDate],Amazon[DeliveryDate])) -> 9
A5: =LEFT(Amazon[Brand],3) -> ZTE | C5: =UPPER(LEFT(Amazon[Brand],3)) -> ZTE | E5: =LOWER(RIGHT(Amazon[SellerID],2)) -> 58 | G5: =UPPER(Amazon[CustomerName]) -> HITESH VERMA | I5: =SUMIF(Amazon_Data!L:L,"Delivered",Amazon_Data!M:M) -> 7650453.1 | K5: =SUMIF(Amazon[OrderStatus],"Delivered",Amazon[FinalPrice]) -> 7650453.1 | Z5: =IF(Amazon[SellerRating]>=4,"true","false") -> true | AI5: ZTE | AJ5: =SUMIFS(Amazon[FinalPrice],Amazon[Brand],AI5) -> 1021437.2 | BK5: =ABS(_xlfn.DAYS(Amazon[OrderDate],Amazon[DeliveryDate])) -> 6
A6: =LEFT(Amazon[Brand],3) -> LG | C6: =UPPER(LEFT(Amazon[Brand],3)) -> LG | E6: =LOWER(RIGHT(Amazon[SellerID],2)) -> 86 | G6: =UPPER(Amazon[CustomerName]) -> HITESH SHARMA | I6: Where Delivered revenue.. Using sumifs | Z6: =IF(Amazon[SellerRating]>=4,"true","false") -> true | AI6: LG | AJ6: =SUMIFS(Amazon[FinalPrice],Amazon[Brand],AI6) -> 2255586.6 | BA6: 85135 | BK6: =ABS(_xlfn.DAYS(Amazon[OrderDate],Amazon[DeliveryDate])) -> 9
A7: =LEFT(Amazon[Brand],3) -> HTC | C7: =UPPER(LEFT(Amazon[Brand],3)) -> HTC | E7: =LOWER(RIGHT(Amazon[SellerID],2)) -> 35 | G7: =UPPER(Amazon[CustomerName]) -> LAKSHMI REDDY | I7: =SUMIFS(Amazon_Data!M:M,Amazon_Data!L:L,Amazon_Data!L8) -> 7650453.1 | K7: =SUMIFS(Amazon[FinalPrice],Amazon[OrderStatus],"Delivered") -> 7650453.1 | Z7: =IF(Amazon[SellerRating]>=4,"true","false") -> false | AI7: HTC | AJ7: =SUMIFS(Amazon[FinalPrice],Amazon[Brand],AI7) -> 3436426.8 | BK7: =ABS(_xlfn.DAYS(Amazon[OrderDate],Amazon[DeliveryDate])) -> 5
A8: =LEFT(Amazon[Brand],3) -> Del | C8: =UPPER(LEFT(Amazon[Brand],3)) -> DEL | E8: =LOWER(RIGHT(Amazon[SellerID],2)) -> 75 | G8: =UPPER(Amazon[CustomerName]) -> POOJA IYER | I8: TotaL delivered Products | Z8: =IF(Amazon[SellerRating]>=4,"true","false") -> false | AI8: Dell | AJ8: =SUMIFS(Amazon[FinalPrice],Amazon[Brand],AI8) -> 554347.75 | BK8: =ABS(_xlfn.DAYS(Amazon[OrderDate],Amazon[DeliveryDate])) -> 7
A9: =LEFT(Amazon[Brand],3) -> App | C9: =UPPER(LEFT(Amazon[Brand],3)) -> APP | E9: =LOWER(RIGHT(Amazon[SellerID],2)) -> 32 | G9: =UPPER(Amazon[CustomerName]) -> HITESH REDDY | I9: =COUNTIF(Amazon_Data!L:L,Amazon_Data!L14) -> 39 | K9: =COUNTIF(Amazon[OrderStatus],"delivered") -> 39 | Z9: =IF(Amazon[SellerRating]>=4,"true","false") -> false | AI9: Apple | AJ9: =SUMIFS(Amazon[FinalPrice],Amazon[Brand],AI9) -> 3156674.5 | BD9: shiva | BK9: =ABS(_xlfn.DAYS(Amazon[OrderDate],Amazon[DeliveryDate])) -> 7
A10: =LEFT(Amazon[Brand],3) -> App | C10: =UPPER(LEFT(Amazon[Brand],3)) -> APP | E10: =LOWER(RIGHT(Amazon[SellerID],2)) -> 37 | G10: =UPPER(Amazon[CustomerName]) -> ARJUN PATEL | I10: count orders from bang | Z10: =IF(Amazon[SellerRating]>=4,"true","false") -> false | AI10: Oppo | AJ10: =SUMIFS(Amazon[FinalPrice],Amazon[Brand],AI10) -> 2256308.9 | BK10: =ABS(_xlfn.DAYS(Amazon[OrderDate],Amazon[DeliveryDate])) -> 11
A11: =LEFT(Amazon[Brand],3) -> Mi | C11: =UPPER(LEFT(Amazon[Brand],3)) -> MI | E11: =LOWER(RIGHT(Amazon[SellerID],2)) -> 33 | G11: =UPPER(Amazon[CustomerName]) -> RAVI VERMA | I11: =SUMIFS(Amazon_Data!I:I,Amazon_Data!D:D,Amazon[[#This Row],[Location]]) -> 41 | K11: =SUMIF(Amazon_Data!D:D,Amazon_Data!D14,Amazon_Data!I:I) -> 41 | Z11: =IF(Amazon[SellerRating]>=4,"true","false") -> false | AI11: Samsung | AJ11: =SUMIFS(Amazon[FinalPrice],Amazon[Brand],AI11) -> 2056416.9 | BK11: =ABS(_xlfn.DAYS(Amazon[OrderDate],Amazon[DeliveryDate])) -> 6
A12: =LEFT(Amazon[Brand],3) -> LG | C12: =UPPER(LEFT(Amazon[Brand],3)) -> LG | E12: =LOWER(RIGHT(Amazon[SellerID],2)) -> 11 | G12: =UPPER(Amazon[CustomerName]) -> AMIT SHARMA | K12: =SUMIFS(Amazon_Data!I:I,Amazon_Data!D:D,Amazon_Data!D14) -> 41 | Z12: =IF(Amazon[SellerRating]>=4,"true","false") -> false | AI12: Sony | AJ12: =SUMIFS(Amazon[FinalPrice],Amazon[Brand],AI12) -> 2485374.1 | BK12: =ABS(_xlfn.DAYS(Amazon[OrderDate],Amazon[DeliveryDate])) -> 5
A13: =LEFT(Amazon[Brand],3) -> Opp | C13: =UPPER(LEFT(Amazon[Brand],3)) -> OPP | E13: =LOWER(RIGHT(Amazon[SellerID],2)) -> 76 | G13: =UPPER(Amazon[CustomerName]) -> AMIT VERMA | I13: find the highest unit price | Z13: =IF(Amazon[SellerRating]>=4,"true","false") -> false | AI13: Hindustan Unilever | AJ13: =SUMIFS(Amazon[FinalPrice],Amazon[Brand],AI13) -> 949738.2 | BF13: =INDIRECT(BD9) -> 85135 | BK13: =ABS(_xlfn.DAYS(Amazon[OrderDate],Amazon[DeliveryDate])) -> 8 | BV13: 0.8
A14: =LEFT(Amazon[Brand],3) -> LG | C14: =UPPER(LEFT(Amazon[Brand],3)) -> LG | E14: =LOWER(RIGHT(Amazon[SellerID],2)) -> 23 | G14: =UPPER(Amazon[CustomerName]) -> NEHA GUPTA | I14: =MAX(Amazon[UnitPrice]) -> 119513 | K14: =MAX(Amazon[UnitPrice]) -> 119513 | AI14: Nikon | AJ14: =SUMIFS(Amazon[FinalPrice],Amazon[Brand],AI14) -> 1667041.7 | AO14: =AVERAGEIFS(Amazon_Data!J:J,Amazon_Data!E:E,Amazon_Data!E9) -> 69148.5 | BK14: =ABS(_xlfn.DAYS(Amazon[OrderDate],Amazon[DeliveryDate])) -> 10 | BV14: 1.9
A15: =LEFT(Amazon[Brand],3) -> Viv | C15: =UPPER(LEFT(Amazon[Brand],3)) -> VIV | E15: =LOWER(RIGHT(Amazon[SellerID],2)) -> 21 | G15: =UPPER(Amazon[CustomerName]) -> LAKSHMI VERMA | AI15: Godrej | AJ15: =SUMIFS(Amazon[FinalPrice],Amazon[Brand],AI15) -> 1243670.9 | BK15: =ABS(_xlfn.DAYS(Amazon[OrderDate],Amazon[DeliveryDate])) -> 10 | BV15: 5 | CA15: cat | CB15: pro
A16: =LEFT(Amazon[Brand],3) -> Sam | C16: =UPPER(LEFT(Amazon[Brand],3)) -> SAM | E16: =LOWER(RIGHT(Amazon[SellerID],2)) -> 61 | G16: =UPPER(Amazon[CustomerName]) -> RAVI PATEL | I16: Find the loweset quantity ordered | BK16: =ABS(_xlfn.DAYS(Amazon[OrderDate],Amazon[DeliveryDate])) -> 4 | BV16: 3.7 | CA16: mobile | CB16: mi
A17: =LEFT(Amazon[Brand],3) -> LG | C17: =UPPER(LEFT(Amazon[Brand],3)) -> LG | E17: =LOWER(RIGHT(Amazon[SellerID],2)) -> 92 | G17: =UPPER(Amazon[CustomerName]) -> POOJA REDDY | I17: =MIN(Amazon[Quantity]) -> 1 | AR17: =Amazon[Quantity]*Amazon[UnitPrice]*#REF!% -> #REF! | BK17: =ABS(_xlfn.DAYS(Amazon[OrderDate],Amazon[DeliveryDate])) -> 10 | BS17: =_xlfn.IFS( BV13<1, "Very Worst", BV13<2, "WORST", BV13<3, "Below Average", BV13<4, "GOOD", BV13<=5, "Best" ) -> Very Worst | BV17: 4.1 | BY17: =_xlfn.TEXTJOIN("",TRUE,LEFT(Amazon[Location],2),RIGHT(Amazon[OrderID],2)) -> Ah16 | CA17: laptop | CB17: hp
A18: =LEFT(Amazon[Brand],3) -> HTC | C18: =UPPER(LEFT(Amazon[Brand],3)) -> HTC | E18: =LOWER(RIGHT(Amazon[SellerID],2)) -> 27 | G18: =UPPER(Amazon[CustomerName]) -> ZOYA VERMA | AO18: =COUNTIFS(Amazon[DeliveryDate],">="&DATE(2023,1,1), Amazon[DeliveryDate],"<"&DATE(2024,1,1)) -> 21 | AQ18: =Amazon[UnitPrice]*Amazon[Quantity]*Amazon[Discounts%]% -> 438.68 | BK18: =ABS(_xlfn.DAYS(Amazon[OrderDate],Amazon[DeliveryDate])) -> 11 | BS18: =_xlfn.IFS( BV14<1, "Very Worst", BV14<2, "WORST", BV14<3, "Below Average", BV14<4, "GOOD", BV14<=5, "Best" ) -> WORST | BV18: 5 | CA18: mobile | CB18: vivo
A19: =LEFT(Amazon[Brand],3) -> HTC | C19: =UPPER(LEFT(Amazon[Brand],3)) -> HTC | E19: =LOWER(RIGHT(Amazon[SellerID],2)) -> 01 | G19: =UPPER(Amazon[CustomerName]) -> NEHA IYER | I19: extract the year from order date | X19: shiva.parimi@gmail.com | AQ19: =Amazon[UnitPrice]*Amazon[Quantity]*Amazon[Discounts%]% -> 114.003 | BK19: =ABS(_xlfn.DAYS(Amazon[OrderDate],Amazon[DeliveryDate])) -> 3 | BS19: =_xlfn.IFS( BV15<1, "Very Worst", BV15<2, "WORST", BV15<3, "Below Average", BV15<4, "GOOD", BV15<=5, "Best" ) -> Best
A20: =LEFT(Amazon[Brand],3) -> Son | C20: =UPPER(LEFT(Amazon[Brand],3)) -> SON | E20: =LOWER(RIGHT(Amazon[SellerID],2)) -> 33 | G20: =UPPER(Amazon[CustomerName]) -> ZOYA RAO | I20: =YEAR(Amazon[OrderDate]) -> 2021 | AQ20: =Amazon[UnitPrice]*Amazon[Quantity]*Amazon[Discounts%]% -> 77.132 | BK20: =ABS(_xlfn.DAYS(Amazon[OrderDate],Amazon[DeliveryDate])) -> 9 | BS20: =_xlfn.IFS( BV16<1, "Very Worst", BV16<2, "WORST", BV16<3, "Below Average", BV16<4, "GOOD", BV16<=5, "Best" ) -> GOOD
A21: =LEFT(Amazon[Brand],3) -> Hin | C21: =UPPER(LEFT(Amazon[Brand],3)) -> HIN | E21: =LOWER(RIGHT(Amazon[SellerID],2)) -> 05 | G21: =UPPER(Amazon[CustomerName]) -> SANJAY RAO | X21: extract domain name from email | BK21: =ABS(_xlfn.DAYS(Amazon[OrderDate],Amazon[DeliveryDate])) -> 12 | BS21: =_xlfn.IFS( BV17<1, "Very Worst", BV17<2, "WORST", BV17<3, "Below Average", BV17<4, "GOOD", BV17<=5, "Best" ) -> Best
A22: =LEFT(Amazon[Brand],3) -> Nik | C22: =UPPER(LEFT(Amazon[Brand],3)) -> NIK | E22: =LOWER(RIGHT(Amazon[SellerID],2)) -> 15 | G22: =UPPER(Amazon[CustomerName]) -> ARJUN GUPTA | I22: extract month name from delivery date | T22: weather its weekend or weekday | X22: after @ | AI22: =COUNTIFS(Amazon[PaymentType],"Card",Amazon[Quantity],">2") -> 23 | BK22: =ABS(_xlfn.DAYS(Amazon[OrderDate],Amazon[DeliveryDate])) -> 10 | BS22: =_xlfn.IFS( BV18<1, "Very Worst", BV18<2, "WORST", BV18<3, "Below Average", BV18<4, "GOOD", BV18<=5, "Best" ) -> Best
A23: =LEFT(Amazon[Brand],3) -> ZTE | C23: =UPPER(LEFT(Amazon[Brand],3)) -> ZTE | E23: =LOWER(RIGHT(Amazon[SellerID],2)) -> 44 | G23: =UPPER(Amazon[CustomerName]) -> POOJA PATEL | I23: =TEXT(Amazon[DeliveryDate],"MMM") -> Sep | K23: =TEXT(Amazon[DeliveryDate],"MMM") -> Sep | R23: Q*Unit price | T23: =IF(WEEKDAY(Amazon[OrderDate],2)>=6,"Weekend","WeekDay") -> WeekDay | X23: before . | BK23: =ABS(_xlfn.DAYS(Amazon[OrderDate],Amazon[DeliveryDate])) -> 7 | BS23: =_xlfn.IFS( BV19<1, "Very Worst", BV19<2, "WORST", BV19<3, "Below Average", BV19<4, "GOOD", BV19<=5, "Best" ) -> Very Worst
A24: =LEFT(Amazon[Brand],3) -> HTC | C24: =UPPER(LEFT(Amazon[Brand],3)) -> HTC | E24: =LOWER(RIGHT(Amazon[SellerID],2)) -> 30 | G24: =UPPER(Amazon[CustomerName]) -> ARJUN PATEL | I24: =TEXT(Amazon[DeliveryDate],"MMM") -> Jul | K24: =TEXT(Amazon[DeliveryDate],"MMM") -> Jul | R24: =SUM(Amazon_Data!I2*Amazon_Data!J2) -> 310092 | T24: =IF(WEEKDAY(Amazon[OrderDate],2)>=6,"Weekend","WeekDay") -> Weekend | X24: =FIND("@",X19,6) -> 13 | Z24: =LEN(X19) -> 22 | BK24: =ABS(_xlfn.DAYS(Amazon[OrderDate],Amazon[DeliveryDate])) -> 5 | BS24: =_xlfn.IFS( BV20<1, "Very Worst", BV20<2, "WORST", BV20<3, "Below Average", BV20<4, "GOOD", BV20<=5, "Best" ) -> Very Worst
A25: =LEFT(Amazon[Brand],3) -> App | C25: =UPPER(LEFT(Amazon[Brand],3)) -> APP | E25: =LOWER(RIGHT(Amazon[SellerID],2)) -> 93 | G25: =UPPER(Amazon[CustomerName]) -> MANOJ GUPTA | I25: =TEXT(Amazon[DeliveryDate],"MMM") -> Dec | K25: =TEXT(Amazon[DeliveryDate],"MMM") -> Dec | R25: =SUM(Amazon_Data!I3*Amazon_Data!J3) -> 92974 | T25: =IF(WEEKDAY(Amazon[OrderDate],2)>=6,"Weekend","WeekDay") -> WeekDay | BK25: =ABS(_xlfn.DAYS(Amazon[OrderDate],Amazon[DeliveryDate])) -> 11 | BS25: =_xlfn.IFS( BV21<1, "Very Worst", BV21<2, "WORST", BV21<3, "Below Average", BV21<4, "GOOD", BV21<=5, "Best" ) -> Very Worst
A26: =LEFT(Amazon[Brand],3) -> Son | C26: =UPPER(LEFT(Amazon[Brand],3)) -> SON | E26: =LOWER(RIGHT(Amazon[SellerID],2)) -> 57 | G26: =UPPER(Amazon[CustomerName]) -> HITESH REDDY | I26: =TEXT(Amazon[DeliveryDate],"MMM") -> Apr | K26: =TEXT(Amazon[DeliveryDate],"MMM") -> Apr | R26: =SUM(Amazon_Data!I4*Amazon_Data!J4) -> 133546 | T26: =IF(WEEKDAY(Amazon[OrderDate],2)>=6,"Weekend","WeekDay") -> Weekend | X26: =SEARCH(".",X19,FIND("@",X19,6)) -> 19 | BK26: =ABS(_xlfn.DAYS(Amazon[OrderDate],Amazon[DeliveryDate])) -> 7 | BS26: =_xlfn.IFS( BV22<1, "Very Worst", BV22<2, "WORST", BV22<3, "Below Average", BV22<4, "GOOD", BV22<=5, "Best" ) -> Very Worst
A27: =LEFT(Amazon[Brand],3) -> HTC | C27: =UPPER(LEFT(Amazon[Brand],3)) -> HTC | E27: =LOWER(RIGHT(Amazon[SellerID],2)) -> 23 | G27: =UPPER(Amazon[CustomerName]) -> NEHA SHARMA | K27: =TEXT(Amazon[DeliveryDate],"MMM") -> Feb | R27: =SUM(Amazon_Data!I5*Amazon_Data!J5) -> 231910 | T27: =IF(WEEKDAY(Amazon[OrderDate],2)>=6,"Weekend","WeekDay") -> WeekDay | AE27: =LEN(FIND("m",X19,FIND("@",X19,6))) -> 2 | BK27: =ABS(_xlfn.DAYS(Amazon[OrderDate],Amazon[DeliveryDate])) -> 10 | BS27: =_xlfn.IFS( BV23<1, "Very Worst", BV23<2, "WORST", BV23<3, "Below Average", BV23<4, "GOOD", BV23<=5, "Best" ) -> Very Worst
A28: =LEFT(Amazon[Brand],3) -> God | C28: =UPPER(LEFT(Amazon[Brand],3)) -> GOD | E28: =LOWER(RIGHT(Amazon[SellerID],2)) -> 61 | G28: =UPPER(Amazon[CustomerName]) -> AMIT VERMA | L28: shivaparimi@gmail.com | O28: =ISNUMBER(SEARCH("@",L28,8)) -> TRUE | P28: =SEARCH("@",L28,8) -> 12 | R28: =SUM(Amazon_Data!I6*Amazon_Data!J6) -> 139554 | T28: =IF(WEEKDAY(Amazon[OrderDate],2)>=6,"Weekend","WeekDay") -> Weekend | Y28: 22 | Z28: 13 | AA28: 19 | BK28: =ABS(_xlfn.DAYS(Amazon[OrderDate],Amazon[DeliveryDate])) -> 8 | BS28: =_xlfn.IFS( BV24<1, "Very Worst", BV24<2, "WORST", BV24<3, "Below Average", BV24<4, "GOOD", BV24<=5, "Best" ) -> Very Worst
A29: =LEFT(Amazon[Brand],3) -> Del | C29: =UPPER(LEFT(Amazon[Brand],3)) -> DEL | E29: =LOWER(RIGHT(Amazon[SellerID],2)) -> 40 | G29: =UPPER(Amazon[CustomerName]) -> LAKSHMI SHARMA | I29: If Email contains Gamil or not .? | L29: shivaparimigamil.com | O29: =ISNUMBER(SEARCH("@",L29,8)) -> FALSE | P29: =SEARCH("@",L29,8) -> #VALUE! | R29: =SUM(Amazon_Data!I7*Amazon_Data!J7) -> 78171 | T29: =IF(WEEKDAY(Amazon[OrderDate],2)>=6,"Weekend","WeekDay") -> Weekend | Z29: > | AA29: < | BK29: =ABS(_xlfn.DAYS(Amazon[OrderDate],Amazon[DeliveryDate])) -> 8 | BS29: =_xlfn.IFS( BV25<1, "Very Worst", BV25<2, "WORST", BV25<3, "Below Average", BV25<4, "GOOD", BV25<=5, "Best" ) -> Very Worst
I30: =ISNUMBER(SEARCH("@",Amazon[Email],10)) -> TRUE | R30: =SUM(Amazon_Data!I8*Amazon_Data!J8) -> 51542 | T30: =IF(WEEKDAY(Amazon[OrderDate],2)>=6,"Weekend","WeekDay") -> WeekDay | BS30: =_xlfn.IFS( BV26<1, "Very Worst", BV26<2, "WORST", BV26<3, "Below Average", BV26<4, "GOOD", BV26<=5, "Best" ) -> Very Worst
I31: =ISNUMBER(SEARCH("@",Amazon[Email],10)) -> TRUE | R31: =SUM(Amazon_Data!I9*Amazon_Data!J9) -> 283740 | T31: =IF(WEEKDAY(Amazon[OrderDate],2)>=6,"Weekend","WeekDay") -> Weekend | BS31: =_xlfn.IFS( BV27<1, "Very Worst", BV27<2, "WORST", BV27<3, "Below Average", BV27<4, "GOOD", BV27<=5, "Best" ) -> Very Worst
I32: =ISNUMBER(SEARCH("@",Amazon[Email],10)) -> TRUE | R32: =SUM(Amazon_Data!I10*Amazon_Data!J10) -> 285415 | T32: =IF(WEEKDAY(Amazon[OrderDate],2)>=6,"Weekend","WeekDay") -> WeekDay | Z32: =MID(X19,FIND("@",X19)+1,FIND(".",X19,FIND("@",X19))-FIND("@",X19)-1) -> gmail
I33: =ISNUMBER(SEARCH("@",Amazon[Email],10)) -> TRUE | L33: =ISNUMBER(SEARCH("@",Amazon[Email],6)) -> TRUE | T33: =IF(WEEKDAY(Amazon[OrderDate],2)>=6,"Weekend","WeekDay") -> Weekend | Z33: =MID(X19,FIND("@",X19)+1,FIND(".",X19,FIND("@",X19))-FIND("@",X19)-1) -> gmail
I34: =ISNUMBER(SEARCH("@",Amazon[Email],10)) -> TRUE | N34: Brand+ Model | T34: =IF(WEEKDAY(Amazon[OrderDate],2)>=6,"Weekend","WeekDay") -> WeekDay
N35: =Amazon_Data!E2&" _"&Amazon_Data!F2 -> Mi _Mi Soundbar | T35: =IF(WEEKDAY(Amazon[OrderDate],2)>=6,"Weekend","WeekDay") -> Weekend
N36: =_xlfn.CONCAT(Amazon_Data!E2,"_",Amazon_Data!F2) -> Mi_Mi Soundbar
I38: =FIND(" ",G29) -> 8
A39: =_xlfn.TEXTJOIN(" , ",TRUE,Amazon[CustomerName]) -> Zoya Verma , Sanjay Kapoor , Amit Gupta , Hitesh Verma , Hitesh Sharma , Lakshmi Reddy , Pooja Iyer , Hitesh Reddy , Arjun Patel , Ravi Verma , Amit Sharma , Amit Verma , Neha Gupta , Lakshmi Verma , Ravi Patel , Pooja Reddy , Zoya Verma , Neha Iyer , Zoya Rao , Sanjay Rao , Arjun Gupta , Pooja Patel , Arjun Patel , Manoj Gupta , Hitesh Reddy , Neha Sharma , Amit Verma , Lakshmi Sharma , Ravi Verma , Pooja Verma , Neha Sharma , Ravi Verma , Zoya Reddy , Lakshmi Rao , Hitesh Iyer , Kiran Iyer , Kiran Rao , Amit Gupta , Sanjay Gupta , Ravi Kapoor , Lakshmi Verma , Kiran Rao , Pooja Gupta , Neha Iyer , Zoya Iyer , Pooja Verma , Sanjay Reddy , Arjun Rao , Kiran Verma , Hitesh Gupta , Kiran Patel , Lakshmi Sharma , Pooja Iyer , Manoj Sharma , Ravi Rao , Kiran Iyer , Sanjay Reddy , Manoj Patel , Zoya Reddy , Neha Iyer , Sanjay Kapoor , Ravi Rao , Kiran Gupta , Ravi Rao , Pooja Rao , Zoya Reddy , Zoya Iyer , Sanjay Patel , Lakshmi Iyer , Neha Iyer , Divya Gupta , Arjun Verma , Hitesh Verma , Kiran Reddy , Neha Rao , Ravi Verma , Neha Verma , Arjun Patel , Arjun Gupta , Hitesh Verma , Kiran Patel , Lakshmi Reddy , Neha Verma , Hitesh Reddy , Arjun Reddy , Manoj Patel , Amit Rao , Ravi Reddy , Kiran Verma , Sanjay Patel , Divya Kapoor , Amit Verma , Kiran Kapoor , Amit Verma , Kiran Rao , Ravi Reddy , Kiran Gupta , Kiran Rao , Pooja Sharma , Sanjay Rao , Hitesh Rao , Neha Reddy , Kiran Rao , Pooja Patel , Hitesh Iyer , Lakshmi Kapoor , Neha Gupta , Lakshmi Rao , Zoya Gupta , Zoya Sharma , Arjun Iyer , Manoj Kapoor , Kiran Rao , Divya Reddy , Hitesh Sharma , Manoj Gupta , Kiran Gupta , Kiran Gupta , Ravi Verma , Pooja Verma , Sanjay Patel , Neha Verma , Lakshmi Reddy , Amit Verma , Amit Iyer , Zoya Patel , Manoj Gupta , Pooja Kapoor , Zoya Iyer , Lakshmi Patel , Amit Rao , Amit Verma , Amit Sharma , Manoj Reddy , Divya Patel , Manoj Patel , Pooja Patel , Lakshmi Patel , Kiran Iyer , Kiran Sharma , Amit Iyer , Hitesh Kapoor , Neha Gupta , Divya Verma , Lakshmi Kapoor , Neha Sharma , Hitesh Gupta , Divya Reddy , Zoya Iyer , Hitesh Iyer | I39: =LEFT(G29,FIND(" ",G29)) -> LAKSHMI
I40: =LEFT(G29,FIND(" ",G29,1)) -> LAKSHMI | L40: remove customer name spaces
I41: =RIGHT(G29,LEN(G29)-LEFT(FIND(" ",G29))) -> SHARMA | J41: =LEN(I41) -> 6 | L41: 1. Trim tariling spaces | M41: =TRIM(G29) -> LAKSHMI SHARMA
...
