Workbook

Sheet Revenue per State
A3: STATE | B3: Revenue
A4: Andhra Pradesh | B4: 6236719
A5: Karnataka | B5: 6901268
A6: Kerala | B6: 6065930
A7: Tamil Nadu | B7: 9392321
A8: Telangana | B8: 4509128
A9: Grand Total | B9: 33105366

Sheet CAT_QUANTITY
A3: PRODUCT_CTG | B3: Sum of QUANTITY
A4: car | B4: 5
A5: Laptop | B5: 299
A6: Smartphone | B6: 163
A7: TV | B7: 2
A8: WATCH | B8: 4
A9: Grand Total | B9: 473

Sheet ORDERS_TREND
A1: ORDERDATE | B1: Sum of QUANTITY
A2: 42032 | B2: 3
A3: 42051 | B3: 4
A4: 42117 | B4: 2
A5: 42147 | B5: 1
A6: 42154 | B6: 4
A7: 42178 | B7: 5
A8: 42319 | B8: 4
A9: 42334 | B9: 3
A10: 42337 | B10: 5
A11: 42368 | B11: 2
A12: 42377 | B12: 5
A13: 42572 | B13: 3
... A156: 45994 | B156: 2
A157: Grand Total | B157: 473

Sheet SALES
A1: PRODUCT_CTG | B1: BRAND_NAME | C1: PRODUCT_NAME | D1: SALEID | E1: QUANTITY | F1: PRICE_PER_UNIT | G1: Invoice Price | H1: CITY | I1: STATE | J1: DAY | K1: MONTH | L1: YEAR | M1: ORDERDATE | N1: SHIPEDDATE | O1: OUTFORDELIVERY | P1: DELIVERY | Q1: CUSTOMERKEY | R1: od_dd-d | S1: Late_Delivery
A2: car | B2: ACER | C2: Predator Helios | D2: S1001 | E2: 5 | F2: 62011 | G2: =Sales[[#This Row],[QUANTITY]]*Sales[[#This Row],[PRICE_PER_UNIT]] -> 310055 | H2: Trivandrum | I2: Kerala | J2: 11 | K2: 9 | L2: 2019 | M2: 43719 | N2: 43723 | O2: 43724 | P2: 43728 | Q2: 22 | R2: =P2-M2 -> 9 | S2: =IF(Sales[[#This Row],[od_dd-d]]>7,"Late_Delivery","In_Time") -> Late_Delivery
A3: Smartphone | B3: Nothing | C3: Nothing Phone 2 | D3: S1110 | E3: 5 | F3: 56642 | G3: =Sales[[#This Row],[QUANTITY]]*Sales[[#This Row],[PRICE_PER_UNIT]] -> 283210 | H3: Bangalore | I3: Tamil Nadu | J3: 13 | K3: 5 | L3: 2020 | M3: 43964 | N3: 43967 | O3: 43969 | P3: 43970 | Q3: 21 | R3: =P3-M3 -> 6 | S3: =IF(Sales[[#This Row],[od_dd-d]]>7,"Late_Delivery","In_Time") -> In_Time
A4: Smartphone | B4: Xiaomi | C4: Redmi Note 12 | D4: S1131 | E4: 5 | F4: 53967 | G4: =Sales[[#This Row],[QUANTITY]]*Sales[[#This Row],[PRICE_PER_UNIT]] -> 269835 | H4: Kochi | I4: Kerala | J4: 2 | K4: 2 | L4: 2018 | M4: 43133 | N4: 43136 | O4: 43138 | P4: 43139 | Q4: 7 | R4: =P4-M4 -> 6 | S4: =IF(Sales[[#This Row],[od_dd-d]]>7,"Late_Delivery","In_Time") -> In_Time
A5: Laptop | B5: ASUS | C5: ROG Zephyrus | D5: S1009 | E5: 5 | F5: 91084 | G5: =Sales[[#This Row],[QUANTITY]]*Sales[[#This Row],[PRICE_PER_UNIT]] -> 455420 | H5: Coimbatore | I5: Tamil Nadu | J5: 1 | K5: 3 | L5: 2024 | M5: 45352 | N5: 45355 | O5: 45356 | P5: 45360 | Q5: 20 | R5: =P5-M5 -> 8 | S5: =IF(Sales[[#This Row],[od_dd-d]]>7,"Late_Delivery","In_Time") -> Late_Delivery
A6: Laptop | B6: ASUS | C6: ROG Zephyrus | D6: S1031 | E6: 5 | F6: 104901 | G6: =Sales[[#This Row],[QUANTITY]]*Sales[[#This Row],[PRICE_PER_UNIT]] -> 524505 | H6: Vijayawada | I6: Andhra Pradesh | J6: 8 | K6: 8 | L6: 2020 | M6: 44051 | N6: 44054 | O6: 44057 | P6: 44058 | Q6: 18 | R6: =P6-M6 -> 7 | S6: =IF(Sales[[#This Row],[od_dd-d]]>7,"Late_Delivery","In_Time") -> In_Time
A7: Laptop | B7: LENOVO | C7: ThinkPad E14 | D7: S1040 | E7: 5 | F7: 87400 | G7: =Sales[[#This Row],[QUANTITY]]*Sales[[#This Row],[PRICE_PER_UNIT]] -> 437000 | H7: Madurai | I7: Tamil Nadu | J7: 13 | K7: 3 | L7: 2017 | M7: 42807 | N7: 42809 | O7: 42811 | P7: 42815 | Q7: 18 | R7: =P7-M7 -> 8 | S7: =IF(Sales[[#This Row],[od_dd-d]]>7,"Late_Delivery","In_Time") -> Late_Delivery
A8: Laptop | B8: ASUS | C8: ROG Zephyrus | D8: S1090 | E8: 5 | F8: 79624 | G8: =Sales[[#This Row],[QUANTITY]]*Sales[[#This Row],[PRICE_PER_UNIT]] -> 398120 | H8: Hyderabad | I8: Telangana | J8: 28 | K8: 3 | L8: 2020 | M8: 43918 | N8: 43920 | O8: 43924 | P8: 43927 | Q8: 16 | R8: =P8-M8 -> 9 | S8: =IF(Sales[[#This Row],[od_dd-d]]>7,"Late_Delivery","In_Time") -> Late_Delivery
A9: Smartphone | B9: Oppo | C9: Oppo Reno 10 | D9: S1143 | E9: 5 | F9: 26045 | G9: =Sales[[#This Row],[QUANTITY]]*Sales[[#This Row],[PRICE_PER_UNIT]] -> 130225 | H9: Bangalore | I9: Karnataka | J9: 20 | K9: 3 | L9: 2023 | M9: 45005 | N9: 45008 | O9: 45011 | P9: 45013 | Q9: 8 | R9: =P9-M9 -> 8 | S9: =IF(Sales[[#This Row],[od_dd-d]]>7,"Late_Delivery","In_Time") -> Late_Delivery
A10: Laptop | B10: DELL | C10: Inspiron 15 | D10: S1014 | E10: 5 | F10: 67954 | G10: =Sales[[#This Row],[QUANTITY]]*Sales[[#This Row],[PRICE_PER_UNIT]] -> 339770 | H10: Bangalore | I10: Karnataka | J10: 20 | K10: 7 | L10: 2017 | M10: 42936 | N10: 42938 | O10: 42940 | P10: 42941 | Q10: 1 | R10: =P10-M10 -> 5 | S10: =IF(Sales[[#This Row],[od_dd-d]]>7,"Late_Delivery","In_Time") -> In_Time
A11: Laptop | B11: ASUS | C11: Vivobook 15 | D11: S1037 | E11: 5 | F11: 95837 | G11: =Sales[[#This Row],[QUANTITY]]*Sales[[#This Row],[PRICE_PER_UNIT]] -> 479185 | H11: Visakhapatnam | I11: Andhra Pradesh | J11: 17 | K11: 1 | L11: 2020 | M11: 43847 | N11: 43851 | O11: 43853 | P11: 43854 | Q11: 7 | R11: =P11-M11 -> 7 | S11: =IF(Sales[[#This Row],[od_dd-d]]>7,"Late_Delivery","In_Time") -> In_Time
A12: Laptop | B12: HP | C12: Pavilion 14 | D12: S1045 | E12: 5 | F12: 55340 | G12: =Sales[[#This Row],[QUANTITY]]*Sales[[#This Row],[PRICE_PER_UNIT]] -> 276700 | H12: Madurai | I12: Tamil Nadu | J12: 29 | K12: 11 | L12: 2015 | M12: 42337 | N12: 42338 | O12: 42340 | P12: 42343 | Q12: 11 | R12: =P12-M12 -> 6 | S12: =IF(Sales[[#This Row],[od_dd-d]]>7,"Late_Delivery","In_Time") -> In_Time
A13: Laptop | B13: ASUS | C13: Vivobook 15 | D13: S1046 | E13: 5 | F13: 71100 | G13: =Sales[[#This Row],[QUANTITY]]*Sales[[#This Row],[PRICE_PER_UNIT]] -> 355500 | H13: Visakhapatnam | I13: Andhra Pradesh | J13: 8 | K13: 9 | L13: 2020 | M13: 44082 | N13: 44085 | O13: 44086 | P13: 44090 | Q13: 5 | R13: =P13-M13 -> 8 | S13: =IF(Sales[[#This Row],[od_dd-d]]>7,"Late_Delivery","In_Time") -> Late_Delivery
... A58: Smartphone | B58: Vivo | C58: Vivo V27 | D58: S1155 | E58: 4 | F58: 50654 | G58: =Sales[[#This Row],[QUANTITY]]*Sales[[#This Row],[PRICE_PER_UNIT]] -> 202616 | H58: Kochi | I58: Tamil Nadu | J58: 30 | K58: 5 | L58: 2015 | M58: 42154 | N58: 42155 | O58: 42159 | P58: 42162 | Q58: 14 | R58: =P58-M58 -> 8 | S58: =IF(Sales[[#This Row],[od_dd-d]]>7,"Late_Delivery","In_Time") -> Late_Delivery
A59: Smartphone | B59: Vivo | D59: S1160 | E59: 4 | F59: 71760 | G59: =Sales[[#This Row],[QUANTITY]]*Sales[[#This Row],[PRICE_PER_UNIT]] -> 287040 | H59: Hyderabad | I59: Kerala | J59: 23 | K59: 10 | L59: 2017 | M59: 43031 | N59: 43032 | O59: 43034 | P59: 43037 | Q59: 8 | R59: =P59-M59 -> 6 | S59: =IF(Sales[[#This Row],[od_dd-d]]>7,"Late_Delivery","In_Time") -> In_Time
A60: Laptop | B60: HP | C60: Omen 16 | D60: S1016 | E60: 4 | F60: 95618 | G60: =Sales[[#This Row],[QUANTITY]]*Sales[[#This Row],[PRICE_PER_UNIT]] -> 382472 | H60: Chennai | I60: Tamil Nadu | J60: 18 | K60: 10 | L60: 2017 | M60: 43026 | N60: 43028 | O60: 43031 | P60: 43033 | Q60: 9 | R60: =P60-M60 -> 7 | S60: =IF(Sales[[#This Row],[od_dd-d]]>7,"Late_Delivery","In_Time") -> In_Time
A61: Laptop | B61: HP | C61: Omen 16 | D61: S1075 | E61: 4 | F61: 52476 | G61: =Sales[[#This Row],[QUANTITY]]*Sales[[#This Row],[PRICE_PER_UNIT]] -> 209904 | H61: Mysore | I61: Karnataka | J61: 7 | K61: 9 | L61: 2016 | M61: 42620 | N61: 42623 | O61: 42627 | P61: 42629 | Q61: 9 | R61: =P61-M61 -> 9 | S61: =IF(Sales[[#This Row],[od_dd-d]]>7,"Late_Delivery","In_Time") -> Late_Delivery
A62: Smartphone | B62: Google | C62: Pixel 7 | D62: S1113 | E62: 4 | F62: 77679 | G62: =Sales[[#This Row],[QUANTITY]]*Sales[[#This Row],[PRICE_PER_UNIT]] -> 310716 | H62: Kochi | I62: Telangana | J62: 27 | K62: 2 | L62: 2019 | M62: 43523 | N62: 43524 | O62: 43525 | P62: 43526 | Q62: 17 | R62: =P62-M62 -> 3 | S62: =IF(Sales[[#This Row],[od_dd-d]]>7,"Late_Delivery","In_Time") -> In_Time
A63: Laptop | B63: DELL | C63: XPS 13 | D63: S1055 | E63: 4 | F63: 53632 | G63: =Sales[[#This Row],[QUANTITY]]*Sales[[#This Row],[PRICE_PER_UNIT]] -> 214528 | H63: Visakhapatnam | I63: Andhra Pradesh | J63: 30 | K63: 11 | L63: 2024 | M63: 45626 | N63: 45627 | O63: 45628 | P63: 45631 | Q63: 10 | R63: =P63-M63 -> 5 | S63: =IF(Sales[[#This Row],[od_dd-d]]>7,"Late_Delivery","In_Time") -> In_Time
A64: Laptop | B64: DELL | C64: XPS 13 | D64: S1063 | E64: 4 | F64: 63622 | G64: =Sales[[#This Row],[QUANTITY]]*Sales[[#This Row],[PRICE_PER_UNIT]] -> 254488 | H64: Chennai | I64: Tamil Nadu | J64: 15 | K64: 3 | L64: 2025 | M64: 45731 | N64: 45735 | O64: 45738 | P64: 45741 | Q64: 22 | R64: =P64-M64 -> 10 | S64: =IF(Sales[[#This Row],[od_dd-d]]>7,"Late_Delivery","In_Time") -> Late_Delivery
A65: Laptop | B65: DELL | C65: XPS 13 | D65: S1085 | E65: 4 | F65: 81670 | G65: =Sales[[#This Row],[QUANTITY]]*Sales[[#This Row],[PRICE_PER_UNIT]] -> 326680 | H65: Mysore | I65: Karnataka | J65: 24 | K65: 6 | L65: 2025 | M65: 45832 | N65: 45834 | O65: 45836 | P65: 45838 | Q65: 13 | R65: =P65-M65 -> 6 | S65: =IF(Sales[[#This Row],[od_dd-d]]>7,"Late_Delivery","In_Time") -> In_Time
A66: Laptop | B66: ACER | C66: Predator Helios | D66: S1038 | E66: 3 | F66: 48970 | G66: =Sales[[#This Row],[QUANTITY]]*Sales[[#This Row],[PRICE_PER_UNIT]] -> 146910 | H66: Visakhapatnam | I66: Andhra Pradesh | J66: 5 | K66: 3 | L66: 2018 | M66: 43164 | N66: 43168 | O66: 43169 | P66: 43173 | Q66: 12 | R66: =P66-M66 -> 9 | S66: =IF(Sales[[#This Row],[od_dd-d]]>7,"Late_Delivery","In_Time") -> Late_Delivery
A67: Laptop | B67: ACER | C67: Predator Helios | D67: S1039 | E67: 3 | F67: 99447 | G67: =Sales[[#This Row],[QUANTITY]]*Sales[[#This Row],[PRICE_PER_UNIT]] -> 298341 | H67: Mysore | I67: Karnataka | J67: 30 | K67: 4 | L67: 2020 | M67: 43951 | N67: 43955 | O67: 43957 | P67: 43960 | Q67: 17 | R67: =P67-M67 -> 9 | S67: =IF(Sales[[#This Row],[od_dd-d]]>7,"Late_Delivery","In_Time") -> Late_Delivery
A68: Laptop | B68: ACER | C68: Predator Helios | D68: S1044 | E68: 3 | F68: 49573 | G68: =Sales[[#This Row],[QUANTITY]]*Sales[[#This Row],[PRICE_PER_UNIT]] -> 148719 | H68: Mysore | I68: Karnataka | J68: 6 | K68: 12 | L68: 2019 | M68: 43805 | N68: 43808 | O68: 43810 | P68: 43814 | Q68: 15 | R68: =P68-M68 -> 9 | S68: =IF(Sales[[#This Row],[od_dd-d]]>7,"Late_Delivery","In_Time") -> Late_Delivery
A69: Smartphone | B69: Realme | C69: Realme GT Neo3 | D69: S1119 | E69: 3 | F69: 61792 | G69: =Sales[[#This Row],[QUANTITY]]*Sales[[#This Row],[PRICE_PER_UNIT]] -> 185376 | H69: Hyderabad | I69: Tamil Nadu | J69: 10 | K69: 6 | L69: 2021 | M69: 44357 | N69: 44361 | O69: 44363 | P69: 44366 | Q69: 12 | R69: =P69-M69 -> 9 | S69: =IF(Sales[[#This Row],[od_dd-d]]>7,"Late_Delivery","In_Time") -> Late_Delivery
A70: Smartphone | B70: Nothing | C70: Nothing Phone 2 | D70: S1141 | E70: 3 | F70: 44283 | G70: =Sales[[#This Row],[QUANTITY]]*Sales[[#This Row],[PRICE_PER_UNIT]] -> 132849 | H70: Chennai | I70: Karnataka | J70: 1 | K70: 6 | L70: 2020 | M70: 43983 | N70: 43986 | O70: 43989 | P70: 43991 | Q70: 20 | R70: =P70-M70 -> 8 | S70: =IF(Sales[[#This Row],[od_dd-d]]>7,"Late_Delivery","In_Time") -> Late_Delivery
A71: Smartphone | B71: Nothing | C71: Nothing Phone 2 | D71: S1146 | E71: 3 | F71: 44188 | G71: =Sales[[#This Row],[QUANTITY]]*Sales[[#This Row],[PRICE_PER_UNIT]] -> 132564 | H71: Kochi | I71: Kerala | J71: 21 | K71: 7 | L71: 2016 | M71: 42572 | N71: 42575 | O71: 42577 | P71: 42581 | Q71: 4 | R71: =P71-M71 -> 9 | S71: =IF(Sales[[#This Row],[od_dd-d]]>7,"Late_Delivery","In_Time") -> Late_Delivery
... A147: Laptop | B147: MSI | C147: GF63 Thin | D147: S1022 | E147: 1 | F147: 57087 | G147: =Sales[[#This Row],[QUANTITY]]*Sales[[#This Row],[PRICE_PER_UNIT]] -> 57087 | H147: Vijayawada | I147: Andhra Pradesh | J147: 22 | K147: 3 | L147: 2017 | M147: 42816 | N147: 42820 | O147: 42824 | P147: 42825 | Q147: 7 | R147: =P147-M147 -> 9 | S147: =IF(Sales[[#This Row],[od_dd-d]]>7,"Late_Delivery","In_Time") -> Late_Delivery
A148: Laptop | B148: MSI | C148: GF63 Thin | D148: S1041 | E148: 1 | F148: 94011 | G148: =Sales[[#This Row],[QUANTITY]]*Sales[[#This Row],[PRICE_PER_UNIT]] -> 94011 | H148: Coimbatore | I148: Tamil Nadu | J148: 12 | K148: 9 | L148: 2019 | M148: 43720 | N148: 43722 | O148: 43726 | P148: 43729 | Q148: 5 | R148: =P148-M148 -> 9 | S148: =IF(Sales[[#This Row],[od_dd-d]]>7,"Late_Delivery","In_Time") -> Late_Delivery | Y148: PRODUCT_NAME | Z148: SALEID
A149: Laptop | B149: MSI | C149: Modern 14 | D149: S1054 | E149: 1 | F149: 113879 | G149: =Sales[[#This Row],[QUANTITY]]*Sales[[#This Row],[PRICE_PER_UNIT]] -> 113879 | H149: Coimbatore | I149: Tamil Nadu | J149: 24 | K149: 7 | L149: 2016 | M149: 42575 | N149: 42577 | O149: 42578 | P149: 42580 | Q149: 19 | R149: =P149-M149 -> 5 | S149: =IF(Sales[[#This Row],[od_dd-d]]>7,"Late_Delivery","In_Time") -> In_Time | Y149: Predator Helios | Z149: S1001
A150: Laptop | B150: MSI | C150: GF63 Thin | D150: S1078 | E150: 1 | F150: 45868 | G150: =Sales[[#This Row],[QUANTITY]]*Sales[[#This Row],[PRICE_PER_UNIT]] -> 45868 | H150: Coimbatore | I150: Tamil Nadu | J150: 29 | K150: 4 | L150: 2025 | M150: 45776 | N150: 45780 | O150: 45782 | P150: 45783 | Q150: 10 | R150: =P150-M150 -> 7 | S150: =IF(Sales[[#This Row],[od_dd-d]]>7,"Late_Delivery","In_Time") -> In_Time | Y150: Nothing Phone 2 | Z150: S1110
A151: Laptop | B151: MSI | C151: GF63 Thin | D151: S1096 | E151: 1 | F151: 47082 | G151: =Sales[[#This Row],[QUANTITY]]*Sales[[#This Row],[PRICE_PER_UNIT]] -> 47082 | H151: Chennai | I151: Tamil Nadu | J151: 14 | K151: 11 | L151: 2024 | M151: 45610 | N151: 45613 | O151: 45616 | P151: 45618 | Q151: 7 | R151: =P151-M151 -> 8 | S151: =IF(Sales[[#This Row],[od_dd-d]]>7,"Late_Delivery","In_Time") -> Late_Delivery | Y151: Redmi Note 12 | Z151: S1131
A152: Smartphone | B152: Apple | C152: iPhone 14 | D152: S1137 | E152: 1 | F152: 32893 | G152: =Sales[[#This Row],[QUANTITY]]*Sales[[#This Row],[PRICE_PER_UNIT]] -> 32893 | H152: Bangalore | I152: Tamil Nadu | J152: 12 | K152: 7 | L152: 2025 | M152: 45850 | N152: 45852 | O152: 45855 | P152: 45859 | Q152: 2 | R152: =P152-M152 -> 9 | S152: =IF(Sales[[#This Row],[od_dd-d]]>7,"Late_Delivery","In_Time") -> Late_Delivery | Y152: ROG Zephyrus | Z152: S1009
A153: Smartphone | B153: Vivo | C153: Vivo V27 | D153: S1136 | E153: 1 | F153: 31273 | G153: =Sales[[#This Row],[QUANTITY]]*Sales[[#This Row],[PRICE_PER_UNIT]] -> 31273 | H153: Kochi | I153: Tamil Nadu | J153: 26 | K153: 5 | L153: 2023 | M153: 45072 | N153: 45074 | O153: 45076 | P153: 45078 | Q153: 23 | R153: =P153-M153 -> 6 | S153: =IF(Sales[[#This Row],[od_dd-d]]>7,"Late_Delivery","In_Time") -> In_Time | Y153: ROG Zephyrus | Z153: S1031
A154: Smartphone | B154: Vivo | C154: Vivo V27 | D154: S1140 | E154: 1 | F154: 69307 | G154: =Sales[[#This Row],[QUANTITY]]*Sales[[#This Row],[PRICE_PER_UNIT]] -> 69307 | H154: Madurai | I154: Tamil Nadu | J154: 13 | K154: 12 | L154: 2022 | M154: 44908 | N154: 44909 | O154: 44913 | P154: 44914 | Q154: 16 | R154: =P154-M154 -> 6 | S154: =IF(Sales[[#This Row],[od_dd-d]]>7,"Late_Delivery","In_Time") -> In_Time | Y154: ThinkPad E14 | Z154: S1040
A155: Laptop | B155: HP | C155: Omen 16 | D155: S1003 | E155: 1 | F155: 88403 | G155: =Sales[[#This Row],[QUANTITY]]*Sales[[#This Row],[PRICE_PER_UNIT]] -> 88403 | H155: Madurai | I155: Tamil Nadu | J155: 12 | K155: 2 | L155: 2020 | M155: 43873 | N155: 43874 | O155: 43876 | P155: 43880 | Q155: 22 | R155: =P155-M155 -> 7 | S155: =IF(Sales[[#This Row],[od_dd-d]]>7,"Late_Delivery","In_Time") -> In_Time | Y155: ROG Zephyrus | Z155: S1090
A156: Laptop | B156: HP | C156: Omen 16 | D156: S1043 | E156: 1 | F156: 72235 | G156: =Sales[[#This Row],[QUANTITY]]*Sales[[#This Row],[PRICE_PER_UNIT]] -> 72235 | H156: Mysore | I156: Karnataka | J156: 27 | K156: 3 | L156: 2024 | M156: 45378 | N156: 45382 | O156: 45383 | P156: 45387 | Q156: 23 | R156: =P156-M156 -> 9 | S156: =IF(Sales[[#This Row],[od_dd-d]]>7,"Late_Delivery","In_Time") -> Late_Delivery | Y156: Oppo Reno 10 | Z156: S1143
A157: Laptop | B157: HP | C157: Omen 16 | D157: S1089 | E157: 1 | F157: 61574 | G157: =Sales[[#This Row],[QUANTITY]]*Sales[[#This Row],[PRICE_PER_UNIT]] -> 61574 | H157: Madurai | I157: Tamil Nadu | J157: 2 | K157: 6 | L157: 2024 | M157: 45445 | N157: 45449 | O157: 45452 | P157: 45455 | Q157: 17 | R157: =P157-M157 -> 10 | S157: =IF(Sales[[#This Row],[od_dd-d]]>7,"Late_Delivery","In_Time") -> Late_Delivery | Y157: Inspiron 15 | Z157: S1014
A158: Smartphone | B158: Google | C158: Pixel 7 | D158: S1120 | E158: 1 | F158: 57884 | G158: =Sales[[#This Row],[QUANTITY]]*Sales[[#This Row],[PRICE_PER_UNIT]] -> 57884 | H158: Madurai | I158: Karnataka | J158: 16 | K158: 7 | L158: 2025 | M158: 45854 | N158: 45856 | O158: 45858 | P158: 45861 | Q158: 9 | R158: =P158-M158 -> 7 | S158: =IF(Sales[[#This Row],[od_dd-d]]>7,"Late_Delivery","In_Time") -> In_Time | Y158: Vivobook 15 | Z158: S1037
A159: Laptop | B159: DELL | C159: XPS 13 | D159: S1020 | E159: 1 | F159: 119905 | G159: =Sales[[#This Row],[QUANTITY]]*Sales[[#This Row],[PRICE_PER_UNIT]] -> 119905 | H159: Hyderabad | I159: Telangana | J159: 21 | K159: 1 | L159: 2017 | M159: 42756 | N159: 42760 | O159: 42763 | P159: 42764 | Q159: 2 | R159: =P159-M159 -> 8 | S159: =IF(Sales[[#This Row],[od_dd-d]]>7,"Late_Delivery","In_Time") -> Late_Delivery | Y159: Pavilion 14 | Z159: S1045
...

Sheet FACT_SALES
A1: SALEID | B1: PRODUCT_CTG | C1: BRANDKEY | D1: PRODUCTKEY | E1: STATEKEY | F1: CITYKEY | G1: ORDERDATEKEY | H1: SHIPPEDKEY | I1: OUTFORDELIVERYKEY | J1: DELIVEYDATEKEY | K1: QUANTITY | L1: PRICE_PER_UNIT | M1: CUSTOMERKEY
A2: S1001 | B2: 1 | C2: 1 | D2: 15 | E2: 3 | F2: 8 | G2: 11092019 | H2: 15092019 | I2: 16092019 | J2: 20092019 | K2: 5 | L2: 62011 | M2: 22
A3: S1019 | B3: 1 | C3: 1 | D3: 15 | E3: 1 | F3: 10 | G3: 18052017 | H3: 20052017 | I3: 23052017 | J3: 25052017 | K3: 2 | L3: 57240 | M3: 17
A4: S1025 | B4: 1 | C4: 1 | D4: 15 | E4: 3 | F4: 8 | G4: 11112015 | H4: 13112015 | I4: 16112015 | J4: 18112015 | K4: 4 | L4: 54984 | M4: 16
A5: S1038 | B5: 1 | C5: 1 | D5: 15 | E5: 1 | F5: 10 | G5: 05032018 | H5: 09032018 | I5: 10032018 | J5: 14032018 | K5: 3 | L5: 48970 | M5: 12
A6: S1039 | B6: 1 | C6: 1 | D6: 15 | E6: 2 | F6: 7 | G6: 30042020 | H6: 04052020 | I6: 06052020 | J6: 09052020 | K6: 3 | L6: 99447 | M6: 17
A7: S1044 | B7: 1 | C7: 1 | D7: 15 | E7: 2 | F7: 7 | G7: 06122019 | H7: 09122019 | I7: 11122019 | J7: 15122019 | K7: 3 | L7: 49573 | M7: 15
A8: S1058 | B8: 1 | C8: 1 | D8: 15 | E8: 1 | F8: 10 | G8: 23042015 | H8: 27042015 | I8: 29042015 | J8: 30042015 | K8: 2 | L8: 63680 | M8: 15
A9: S1095 | B9: 1 | C9: 1 | D9: 15 | E9: 3 | F9: 5 | G9: 08072020 | H9: 11072020 | I9: 12072020 | J9: 15072020 | K9: 1 | L9: 67281 | M9: 22
A10: S1101 | B10: 2 | C10: 10 | D10: 9 | E10: 5 | F10: 3 | G10: 23052015 | H10: 26052015 | I10: 27052015 | J10: 28052015 | K10: 1 | L10: 15624 | M10: 20
A11: S1107 | B11: 2 | C11: 13 | D11: 16 | E11: 3 | F11: 6 | G11: 15082021 | H11: 16082021 | I11: 18082021 | J11: 22082021 | K11: 2 | L11: 45254 | M11: 7
A12: S1109 | B12: 2 | C12: 13 | D12: 16 | E12: 3 | F12: 5 | G12: 18072024 | H12: 21072024 | I12: 25072024 | J12: 29072024 | K12: 2 | L12: 50220 | M12: 5
A13: S1110 | B13: 2 | C13: 10 | D13: 9 | E13: 4 | F13: 1 | G13: 13052020 | H13: 16052020 | I13: 18052020 | J13: 19052020 | K13: 5 | L13: 56642 | M13: 21
... A161: S1085 | B161: 1 | C161: 4 | D161: 22 | E161: 2 | F161: 7 | G161: 24062025 | H161: 26062025 | I161: 28062025 | J161: 30062025 | K161: 4 | L161: 81670 | M161: 13

Sheet DIM_TABLES
A2: BRANDKEY | B2: BRAND_NAME | D2: CATG_ID | E2: CATG_NAME | G2: CITYKEY | H2: CITY | J2: PRODUCTKEY | K2: PRODUCT_NAME | N2: STATEKEY | O2: STATE
A3: 1 | B3: ACER | D3: 1 | E3: Laptop | G3: 1 | H3: Bangalore | J3: 1 | K3: Aspire 5 | N3: 3 | O3: Kerala
A4: 2 | B4: Apple | D4: 2 | E4: Smartphone | G4: 2 | H4: Chennai | J4: 2 | K4: Galaxy S23 | N4: 1 | O4: Andhra Pradesh
A5: 3 | B5: ASUS | G5: 3 | H5: Coimbatore | J5: 3 | K5: GF63 Thin | N5: 2 | O5: Karnataka
A6: 4 | B6: DELL | G6: 4 | H6: Hyderabad | J6: 4 | K6: IdeaPad Slim 5 | N6: 5 | O6: Telangana
A7: 5 | B7: Google | G7: 5 | H7: Kochi | J7: 5 | K7: Inspiron 15 | N7: 4 | O7: Tamil Nadu
A8: 6 | B8: HP | G8: 6 | H8: Madurai | J8: 6 | K8: iPhone 14
A9: 7 | B9: LENOVO | G9: 7 | H9: Mysore | J9: 7 | K9: Modern 14
A10: 8 | B10: Motorola | G10: 8 | H10: Trivandrum | J10: 8 | K10: Moto Edge 40
A11: 9 | B11: MSI | G11: 9 | H11: Vijayawada | J11: 9 | K11: Nothing Phone 2
A12: 10 | B12: Nothing | G12: 10 | H12: Visakhapatnam | J12: 10 | K12: Omen 16
A13: 11 | B13: OnePlus | J13: 11 | K13: OnePlus 11
A14: 12 | B14: Oppo | J14: 12 | K14: Oppo Reno 10
A15: 13 | B15: Realme | J15: 13 | K15: Pavilion 14
A16: 14 | B16: Samsung | J16: 14 | K16: Pixel 7
A17: 15 | B17: Vivo | J17: 15 | K17: Predator Helios
A18: 16 | B18: Xiaomi | J18: 16 | K18: Realme GT Neo 3
J19: 17 | K19: Redmi Note 12
J20: 18 | K20: ROG Zephyrus
J21: 19 | K21: ThinkPad E14
J22: 20 | K22: Vivo V27
A23: EMPID | B23: FIRSTNAME | C23: LASTNAME | D23: GENDER | E23: DATEOFBIRTH | J23: 21 | K23: Vivobook 15
A24: 1 | B24: PRANEETH | C24: B | D24: Male | E24: 32300 | J24: 22 | K24: XPS 13
A25: 2 | B25: PARIMI | C25: SHIVA | D25: Male | E25: 32640
A26: 3 | B26: BHANU | C26: T | D26: Male | E26: 32875
A27: 4 | B27: GANESH | C27: T | D27: Female | E27: 33733
A28: 5 | B28: Vinay | C28: Shukla | D28: Male | E28: 33645
A29: 6 | B29: HEMANTH | C29: C | D29: Male | E29: 33039
A30: 7 | B30: TEJASHWAR | C30: M | D30: Male | E30: 33454
A31: 8 | B31: YASHWANTH | C31: CH | D31: MALE | E31: 30020
A32: 9 | B32: KIRAN | C32: B | D32: Male | E32: 31966
A33: 10 | B33: SUBRAT | C33: K | D33: MALE | E33: 31116
A34: 11 | B34: VIJAY | C34: Verma | D34: Male | E34: 32212
A35: 12 | B35: VINEELA | C35: Sinha | D35: FEMALE | E35: 33145
A36: 13 | B36: KUSHALI | C36: Rathi | D36: Female | E36: 34729
... A46: 23 | B46: PIYUSH | C46: S | D46: MALE | E46: 34230

Sheet DIM_DATE
B2: Date | C2: DATEKEY
B3: 42005 | C3: 01012015
B4: 42006 | C4: 02012015
B5: 42007 | C5: 03012015
B6: 42008 | C6: 04012015
B7: 42009 | C7: 05012015
B8: 42010 | C8: 06012015
B9: 42011 | C9: 07012015
B10: 42012 | C10: 08012015
B11: 42013 | C11: 09012015
B12: 42014 | C12: 10012015
B13: 42015 | C13: 11012015
B14: 42016 | C14: 12012015
... B4020: 46022 | C4020: 31122025

Sheet Assignment _A
A1: Section 1: Lookup & Reference (VLOOKUP / XLOOKUP / INDEX-MATCH)
A2: 1. Write a formula to return the Brand Name when a user enters a SALEID. | B2: Using X Lookup Achieved | C2: SALE_ID | D2: BRAND_NAME
C3: S1110 | D3: {=_xlfn.XLOOKUP(C3,SALES!$D$1:$D$161,SALES!$B$1:$B$161,"NOT FOUND",0,1)} -> Nothing
A5: 2. Find the Price per Unit for SALEID S1110 using XLOOKUP. | C5: SALE_ID | D5: BRAND_NAME | E5: Model | F5: Quantity | G5: Unit price
C6: S1117 | D6: {=_xlfn.XLOOKUP(C6,SALES!$D$1:$D$161, SALES!$F$1:$F$161 : SALES!$B$1,"No Matching Data",0,1)} -> Realme | E6: Realme GT Neo3 | F6: S1117 | G6: 1 | H6: 78139
A8: 3. Using INDEX-MATCH, return the CITY & STATE together for SALEID S1095. | C8: SALE_ID | D8: row index num | E8: City | F8: State
C9: S1112 | D9: =MATCH(C9,SALES!$D$1:$D$161,0) -> 98 | E9: {=INDEX(SALES!H:H, D9)} -> Hyderabad | F9: {=INDEX(SALES!I:I,'Assignment _A'!D9,0)} -> Kerala
A11: 4. Lookup the Order Date for Nothing Phone 2 purchased in Hyderabad. | B11: using x lookup and Filter | C11: {=_xlfn.XLOOKUP("Nothing Phone 2"&"Hyderabad",SALES!C:C&SALES!H:H,SALES!M:M,"NOOOOOO",0,1)} -> 44039 | D11: {=_xlfn._xlws.FILTER(SALES!$M$2:$M$161,(SALES!$C$2:$C$161="Nothing Phone 2")*(SALES!$H$2:$H$161="Hyderabad"))} -> 44039
D12: 42703
A15: 5. Return the CustomerKey for the record with highest Quantity sold. | C15: =_xlfn.XLOOKUP(MAX(SALES!E:E),SALES!E:E,(SALES!Q:Q),"NO DATA",0,1) -> 22
A18: 6. For a given Brand Name, return the average Price per Unit dynamically. | C18: BRAND | D18: AVARAGE
C19: HP | D19: =AVERAGEIF(Sales[BRAND_NAME],C19,Sales[PRICE_PER_UNIT]) -> 82926.35
A22: 7. Build a search box: Enter Product Name → return SALEID. | C22: Enter Product Name | D22: SALES ID
C23: XPS 13 | D23: =VLOOKUP(C23,Sales[PRODUCT_NAME]:Sales[SALEID],2,TRUE) -> S1071
D24: =VLOOKUP(C23,Sales[PRODUCT_NAME]:Sales[SALEID],2,TRUE) -> S1071
A26: 8. Find the Shipped Date for sale occurring on 15-08-2021. | C26: Sales Date | D26: Shipped dates
C27: 44423 | D27: {=_xlfn._xlws.FILTER(Sales[ORDERDATE]:Sales[SHIPEDDATE],Sales[ORDERDATE]=C27,"NOTHING")} -> 44423 | E27: 44424
A32: 9. Using XLOOKUP with wildcards, find SALEID containing the word “Predator”. | C32: Search Product Name | D32: Sales ID
C33: Oneplus | D33: =_xlfn.XLOOKUP(C33,Sales[PRODUCT_NAME],Sales[SALEID],"No Matching",1,1) -> S1152
C34: vivobook | D34: =_xlfn.XLOOKUP("*"& C34 & "*",Sales[PRODUCT_NAME],Sales[SALEID],"No Matching",2) -> S1037
A38: 10. Lookup all SALEID for the state Kerala (use FILTER). | C38: State | D38: Sales_Id's
C39: Kerala | D39: {=_xlfn._xlws.FILTER(Sales[SALEID],Sales[STATE]=C39,"NO DATA with state ")} -> S1001
D40: S1131
D41: S1067
D42: S1104
D43: S1152
D44: S1010
D45: S1056
D46: S1124
D47: S1025
D48: S1123
D49: S1076
D50: S1097
D51: S1118
... D69: S1153
A73: 11. Return the latest Delivery date for any ACER product. | C73: Brand | D73: Delhivery Date
C74: ACER | D74: {=TEXT(MAX(_xlfn._xlws.FILTER(Sales[DELIVERY],Sales[BRAND_NAME]=C74," No Delivery Dates")),"DD-MM-YYYY")} -> 21-11-2024
A77: 12. XLOOKUP between two tables: verify if all SALEID exist in a reference list. | C77: {=_xlfn.XLOOKUP(Sales[SALEID],Sales[SALEID],TBL_SALE_ID[SALEID]=Sales[SALEID],"Not matching",0,1)} -> TRUE | D77: {=_xlfn.UNIQUE(_xlfn.ANCHORARRAY(C77))} -> TRUE
C78: TRUE | D78: FALSE
C79: TRUE
...

Sheet ASSIGNMENT_B
A1: Section 2: Date & Time Scenarios
A2: 1. Calculate Order to Delivery Days for each sale. | C2: Order date | D2: Delivered Date | E2: No.of delivery Days
C3: =TODAY() -> 45987 | D3: =TODAY()+18 -> 46005 | E3: =_xlfn.DAYS(D3,C3) -> 18
C4: =TODAY()-80 -> 45907 | D4: =TODAY()-70 -> 45917 | E4: =_xlfn.DAYS(D4,C4) -> 10
A8: 2. Calculate Shipped Delay Days: ShippedDate – OrderDate. | C8: {=MAX(ABS(Sales[ORDERDATE]-Sales[SHIPEDDATE]))} -> 4
A11: 3. Identify orders with weekend deliveries using WEEKDAY(). | C11: {=_xlfn._xlws.FILTER(Sales[DELIVERY],WEEKDAY(Sales[DELIVERY],2)>=6,"NOTHING")} -> 45360
C12: 44058
C13: 42343
C14: 42959
C15: 43653
C16: 42183
C17: 42385
C18: 45451
C19: 43044
C20: 44913
C21: 43120
C22: 44234
C23: 43604
... C49: 42764
A52: 4. Extract Year, Month Name, Quarter from ORDERDATE. | C52: =TODAY() -> 45987 | D52: =YEAR(C52) -> 2025 | E52: =MONTH(C52) -> 11 | F52: =DAY(C52) -> 26 | G52: ="Q"&INT(MONTH(C52-1)/3)+1 -> Q4
C53: =TODAY()-150 -> 45837 | D53: =YEAR(C53) -> 2025 | E53: =MONTH(C53) -> 6 | F53: =DAY(C53) -> 29 | G53: ="Q"&INT(MONTH(C53-1)/3)+1 -> Q3
C54: =TODAY()+200 -> 46187 | D54: =YEAR(C54) -> 2026 | E54: =MONTH(C54) -> 6 | F54: =DAY(C54) -> 14 | G54: ="Q"&INT(MONTH(C54-1)/3)+1 -> Q3
C55: =TODAY()-650 -> 45337 | D55: =YEAR(C55) -> 2024 | E55: =MONTH(C55) -> 2 | F55: =DAY(C55) -> 15 | G55: ="Q"&INT(MONTH(C55-1)/3)+1 -> Q1
C58: Delivered Days
A59: 5. Highlight orders delivered within 3 days of shipping. | C59: {=ABS(Sales[ORDERDATE]-Sales[DELIVERY])} -> 9
C60: 6
C61: 6
C62: 8
C63: 7
C64: 8
C65: 9
C66: 8
C67: 5
C68: 7
C69: 6
C70: 8
C71: 8
... C218: 10
D222: OUT For delivery time in days
A223: 6. Find how many days each order spent in “Out for Delivery”. | D223: {=Sales[DELIVERY]-Sales[OUTFORDELIVERY]} -> 4
...

Sheet ASSIGNMENT_3
A1: Section 3: Text Functions (LEFT, RIGHT, MID, FIND, CONCAT)
A2: 1. Extract the brand initials (e.g., ACER → A). | C2: BRAND_NAMES | D2: Intials
C3: {=_xlfn.UNIQUE(Sales[BRAND_NAME])} -> ACER | D3: =LEFT(C3,1) -> A
C4: Nothing | D4: =LEFT(C4,1) -> N
C5: Xiaomi | D5: =LEFT(C5,1) -> X
C6: ASUS | D6: =LEFT(C6,1) -> A
C7: LENOVO | D7: =LEFT(C7,1) -> L
C8: Oppo | D8: =LEFT(C8,1) -> O
C9: DELL | D9: =LEFT(C9,1) -> D
C10: HP | D10: =LEFT(C10,1) -> H
C11: Samsung | D11: =LEFT(C11,1) -> S
C12: OnePlus | D12: =LEFT(C12,1) -> O
C13: MSI | D13: =LEFT(C13,1) -> M
C14: Google | D14: =LEFT(C14,1) -> G
C15: Realme | D15: =LEFT(C15,1) -> R
... C18: Apple | D18: =LEFT(C18,1) -> A
A21: 2. Extract the State Code (e.g., Kerala → KE). | C21: state_Names | D21: state_code
C22: {=_xlfn.UNIQUE(Sales[STATE])} -> Kerala | D22: =UPPER(LEFT(C22,2)) -> KE
C23: Tamil Nadu | D23: =UPPER(LEFT(C23,2)) -> TA
C24: Andhra Pradesh | D24: =UPPER(LEFT(C24,2)) -> AN
C25: Telangana | D25: =UPPER(LEFT(C25,2)) -> TE
C26: Karnataka | D26: =UPPER(LEFT(C26,2)) -> KA
A30: 3. Separate the Product Name into Model and Version. | C30: Product Names | D30: Model Names | E30: Version Names | F30: Version numbers
C31: {=_xlfn.UNIQUE(Sales[PRODUCT_NAME])} -> #VALUE! | D31: {=_xlfn.TEXTSPLIT(C31," ")} -> #VALUE!
D32: {=_xlfn.TEXTSPLIT(C32," ")} -> #VALUE!
D33: {=_xlfn.TEXTSPLIT(C33," ")} -> #VALUE!
D34: {=_xlfn.TEXTSPLIT(C34," ")} -> #VALUE!
D35: {=_xlfn.TEXTSPLIT(C35," ")} -> #VALUE!
D36: {=_xlfn.TEXTSPLIT(C36," ")} -> #VALUE!
D37: {=_xlfn.TEXTSPLIT(C37," ")} -> #VALUE!
D38: {=_xlfn.TEXTSPLIT(C38," ")} -> #VALUE!
D39: {=_xlfn.TEXTSPLIT(C39," ")} -> #VALUE!
D40: {=_xlfn.TEXTSPLIT(C40," ")} -> #VALUE!
D41: {=_xlfn.TEXTSPLIT(C41," ")} -> #VALUE!
D42: {=_xlfn.TEXTSPLIT(C42," ")} -> #VALUE!
D43: {=_xlfn.TEXTSPLIT(C43," ")} -> #VALUE!
... D54: {=_xlfn.TEXTSPLIT(C54," ")} -> #VALUE!
C55: iphone12 | D55: {=_xlfn.TEXTSPLIT(C55," ")} -> iphone12
A58: 4. Count how many times the word “Phone” appears in PRODUCT_NAME. | D58: =COUNTIFS(C31:C55,"*"&"phone"&"*") -> 1
A61: 5. Join CITY & STATE as City-State using CONCAT. | C61: city | D61: state | E61: city_state
...

Sheet ASSIGNMENT_4
A1: Section 4: Logical (IF, IFS, AND, OR)
A2: 1. How do you use the WORKDAY function to calculate a date after a specific number of workdays? | C2: Specifc date | D2: date after 10 workdays days
C3: =TODAY() -> 45987 | D3: =WORKDAY(C3,10) -> 46001
A5: 2. How do you use the NETWORKDAYS function to calculate the number of workdays between two dates? | C5: Date 1 | D5: Date 2 | E5: No.of Working days
C6: =TODAY()-768 -> 45219 | D6: =TODAY()+678 -> 46665 | E6: =NETWORKDAYS(C6,D6) -> 1033
A9: 3. How do you exclude holidays from the WORKDAY calculation? | C9: Start Date | D9: End Date | E9: finding work days | F9: Finding working days excluding Holidays
C10: 45982 | E10: =WORKDAY(C10,6) -> 45992 | F10: =WORKDAY(C10,6,A13:A14) -> 45993
A12: Holidays
A13: =TODAY()+2 -> 45989
A14: =TODAY()-3 -> 45984
A18: 4. How do you exclude holidays from the NETWORKDAYS calculation? | C18: Start Date | D18: End Date | E18: finding work days | F18: Finding working days excluding Holidays
C19: 45982 | D19: 45991 | E19: =NETWORKDAYS(C19,D19) -> 6 | F19: =NETWORKDAYS(C19,D19,A13:A14) -> 5
A22: 5. How do you calculate a project's end date considering only workdays? | C22: Project Start Date | D22: Project End date | E22: No.of working days
C23: =TODAY()-786 -> 45201 | D23: =TODAY()+567 -> 46554 | E23: =NETWORKDAYS(C23,D23) -> 968
A26: 6. How do you calculate the number of workdays available in a specific month? | B26: today | C26: Month start Date | D26: Month End date | E26: Monthly working days
B27: =TODAY() -> 45987 | C27: =EOMONTH(B27,-1)+1 -> 45962 | D27: =EOMONTH(B27,0) -> 45991 | E27: =NETWORKDAYS(C27,D27) -> 20
A30: Create a column classifying states into South / Non-South region. | B30: Indian Sates | D30: South States
B31: Andhra Pradesh | D31: =IF(ISNUMBER(MATCH(B31, {"Andhra Pradesh","Telangana","Karnataka","Tamil Nadu","Kerala","Puducherry"}, 0)), "SOUTH", "NORTH") -> SOUTH
B32: Arunachal Pradesh | D32: =IF(ISNUMBER(MATCH(B32, {"Andhra Pradesh","Telangana","Karnataka","Tamil Nadu","Kerala","Puducherry"}, 0)), "SOUTH", "NORTH") -> NORTH
B33: Assam | D33: =IF(ISNUMBER(MATCH(B33, {"Andhra Pradesh","Telangana","Karnataka","Tamil Nadu","Kerala","Puducherry"}, 0)), "SOUTH", "NORTH") -> NORTH
B34: Bihar | D34: =IF(ISNUMBER(MATCH(B34, {"Andhra Pradesh","Telangana","Karnataka","Tamil Nadu","Kerala","Puducherry"}, 0)), "SOUTH", "NORTH") -> NORTH
B35: Chhattisgarh | D35: =IF(ISNUMBER(MATCH(B35, {"Andhra Pradesh","Telangana","Karnataka","Tamil Nadu","Kerala","Puducherry"}, 0)), "SOUTH", "NORTH") -> NORTH
B36: Goa | D36: =IF(ISNUMBER(MATCH(B36, {"Andhra Pradesh","Telangana","Karnataka","Tamil Nadu","Kerala","Puducherry"}, 0)), "SOUTH", "NORTH") -> NORTH
B37: Gujarat | D37: =IF(ISNUMBER(MATCH(B37, {"Andhra Pradesh","Telangana","Karnataka","Tamil Nadu","Kerala","Puducherry"}, 0)), "SOUTH", "NORTH") -> NORTH
B38: Haryana | D38: =IF(ISNUMBER(MATCH(B38, {"Andhra Pradesh","Telangana","Karnataka","Tamil Nadu","Kerala","Puducherry"}, 0)), "SOUTH", "NORTH") -> NORTH
B39: Himachal Pradesh | D39: =IF(ISNUMBER(MATCH(B39, {"Andhra Pradesh","Telangana","Karnataka","Tamil Nadu","Kerala","Puducherry"}, 0)), "SOUTH", "NORTH") -> NORTH
B40: Jharkhand | D40: =IF(ISNUMBER(MATCH(B40, {"Andhra Pradesh","Telangana","Karnataka","Tamil Nadu","Kerala","Puducherry"}, 0)), "SOUTH", "NORTH") -> NORTH
B41: Karnataka | D41: =IF(ISNUMBER(MATCH(B41, {"Andhra Pradesh","Telangana","Karnataka","Tamil Nadu","Kerala","Puducherry"}, 0)), "SOUTH", "NORTH") -> SOUTH
B42: Kerala | D42: =IF(ISNUMBER(MATCH(B42, {"Andhra Pradesh","Telangana","Karnataka","Tamil Nadu","Kerala","Puducherry"}, 0)), "SOUTH", "NORTH") -> SOUTH
... B58: West Bengal | D58: =IF(ISNUMBER(MATCH(B58, {"Andhra Pradesh","Telangana","Karnataka","Tamil Nadu","Kerala","Puducherry"}, 0)), "SOUTH", "NORTH") -> NORTH
A62: 7. Mark orders as High Value if Price per Unit > 50,000. | B62: Price - Per UNIT | C62: CAT
B63: {=Sales[PRICE_PER_UNIT]} -> 62011 | C63: {=_xlfn.IFS(B63>=50000,"HIGH",B63>=25000,"MEDIUM",B63<25000,"LOW")} -> HIGH
B64: 56642 | C64: {=_xlfn.IFS(B64>=50000,"HIGH",B64>=25000,"MEDIUM",B64<25000,"LOW")} -> HIGH
B65: 53967 | C65: {=_xlfn.IFS(B65>=50000,"HIGH",B65>=25000,"MEDIUM",B65<25000,"LOW")} -> HIGH
A66: HIGH | B66: 91084 | C66: {=_xlfn.IFS(B66>=50000,"HIGH",B66>=25000,"MEDIUM",B66<25000,"LOW")} -> HIGH
A67: MEDIUM | B67: 104901 | C67: {=_xlfn.IFS(B67>=50000,"HIGH",B67>=25000,"MEDIUM",B67<25000,"LOW")} -> HIGH
A68: LOW | B68: 87400 | C68: {=_xlfn.IFS(B68>=50000,"HIGH",B68>=25000,"MEDIUM",B68<25000,"LOW")} -> HIGH
B69: 79624 | C69: {=_xlfn.IFS(B69>=50000,"HIGH",B69>=25000,"MEDIUM",B69<25000,"LOW")} -> HIGH
B70: 26045 | C70: {=_xlfn.IFS(B70>=50000,"HIGH",B70>=25000,"MEDIUM",B70<25000,"LOW")} -> MEDIUM
B71: 67954 | C71: {=_xlfn.IFS(B71>=50000,"HIGH",B71>=25000,"MEDIUM",B71<25000,"LOW")} -> HIGH
...

Sheet ASSIGNMENT_5
A1: Section 5: Pivot Table, Charts & Data Analysis
A2: 1. Create Pivot Table: Total Revenue per State. | B2: REVENUE_PER_STATE
A5: 2. Create Pivot Table: Quantity by Product Category. | B5: CAT_QUANTITY
A8: 3. Create a monthly sales trend using ORDERDATE.
